/Users/machine/Project/GitHub/Namaskah. app/main.py:48: MovedIn20Warning: The ``declarative_base()`` function is now available as sqlalchemy.orm.declarative_base(). (deprecated since: 2.0) (Background on SQLAlchemy 2.0 at: https://sqlalche.me/e/b8d9)
  Base = declarative_base()
Traceback (most recent call last):
  File "/usr/local/lib/python3.13/site-packages/pydantic/networks.py", line 949, in import_email_validator
    import email_validator
ModuleNotFoundError: No module named 'email_validator'

The above exception was the direct cause of the following exception:

Traceback (most recent call last):
  File "/Users/machine/Project/GitHub/Namaskah. app/main.py", line 145, in <module>
    class RegisterRequest(BaseModel):
        email: EmailStr
        password: str
  File "/usr/local/lib/python3.13/site-packages/pydantic/_internal/_model_construction.py", line 255, in __new__
    complete_model_class(
    ~~~~~~~~~~~~~~~~~~~~^
        cls,
        ^^^^
    ...<3 lines>...
        create_model_module=_create_model_module,
        ^^^^^^^^^^^^^^^^^^^^^^^^^^^^^^^^^^^^^^^^^
    )
    ^
  File "/usr/local/lib/python3.13/site-packages/pydantic/_internal/_model_construction.py", line 648, in complete_model_class
    schema = gen_schema.generate_schema(cls)
  File "/usr/local/lib/python3.13/site-packages/pydantic/_internal/_generate_schema.py", line 729, in generate_schema
    schema = self._generate_schema_inner(obj)
  File "/usr/local/lib/python3.13/site-packages/pydantic/_internal/_generate_schema.py", line 1023, in _generate_schema_inner
    return self._model_schema(obj)
           ~~~~~~~~~~~~~~~~~~^^^^^
  File "/usr/local/lib/python3.13/site-packages/pydantic/_internal/_generate_schema.py", line 856, in _model_schema
    {k: self._generate_md_field_schema(k, v, decorators) for k, v in fields.items()},
        ~~~~~~~~~~~~~~~~~~~~~~~~~~~~~~^^^^^^^^^^^^^^^^^^
  File "/usr/local/lib/python3.13/site-packages/pydantic/_internal/_generate_schema.py", line 1228, in _generate_md_field_schema
    schema, metadata = self._common_field_schema(name, field_info, decorators)
                       ~~~~~~~~~~~~~~~~~~~~~~~~~^^^^^^^^^^^^^^^^^^^^^^^^^^^^^^
  File "/usr/local/lib/python3.13/site-packages/pydantic/_internal/_generate_schema.py", line 1282, in _common_field_schema
    schema = self._apply_annotations(
        source_type,
        annotations + validators_from_decorators,
    )
  File "/usr/local/lib/python3.13/site-packages/pydantic/_internal/_generate_schema.py", line 2227, in _apply_annotations
    schema = get_inner_schema(source_type)
  File "/usr/local/lib/python3.13/site-packages/pydantic/_internal/_schema_generation_shared.py", line 83, in __call__
    schema = self._handler(source_type)
  File "/usr/local/lib/python3.13/site-packages/pydantic/_internal/_generate_schema.py", line 2203, in inner_handler
    schema = self._generate_schema_from_get_schema_method(obj, source_type)
  File "/usr/local/lib/python3.13/site-packages/pydantic/_internal/_generate_schema.py", line 919, in _generate_schema_from_get_schema_method
    schema = get_schema(
        source, CallbackGetCoreSchemaHandler(self._generate_schema_inner, self, ref_mode=ref_mode)
    )
  File "/usr/local/lib/python3.13/site-packages/pydantic/networks.py", line 989, in __get_pydantic_core_schema__
    import_email_validator()
    ~~~~~~~~~~~~~~~~~~~~~~^^
  File "/usr/local/lib/python3.13/site-packages/pydantic/networks.py", line 951, in import_email_validator
    raise ImportError("email-validator is not installed, run `pip install 'pydantic[email]'`") from e
ImportError: email-validator is not installed, run `pip install 'pydantic[email]'`
